2024-06-23 15:15:49,540 INFO    StreamThr :24088 [internal.py:wandb_internal():85] W&B internal server running at pid: 24088, started at: 2024-06-23 15:15:49.539940
2024-06-23 15:15:49,542 DEBUG   HandlerThread:24088 [handler.py:handle_request():158] handle_request: status
2024-06-23 15:15:49,564 INFO    WriterThread:24088 [datastore.py:open_for_write():87] open: d:\University\VU Bachelor Artificial Intelligence\Year 3\Periods 5 and 6\Bachelor Project Artificial Intelligence\Thesis-Project\wandb\run-20240623_151549-fdml4tah\run-fdml4tah.wandb
2024-06-23 15:15:49,565 DEBUG   SenderThread:24088 [sender.py:send():379] send: header
2024-06-23 15:15:49,637 DEBUG   SenderThread:24088 [sender.py:send():379] send: run
2024-06-23 15:15:50,054 ERROR   SenderThread:24088 [internal_api.py:execute():344] 403 response executing GraphQL.
2024-06-23 15:15:50,055 ERROR   SenderThread:24088 [internal_api.py:execute():345] {"errors":[{"message":"permission denied","path":["upsertBucket"],"extensions":{"code":"PERMISSION_ERROR"}}],"data":{"upsertBucket":null}}
2024-06-23 15:15:50,055 ERROR   SenderThread:24088 [sender.py:send_run():1009] It appears that you do not have permission to access the requested resource. Please reach out to the project owner to grant you access. If you have the correct permissions, verify that there are no issues with your networking setup.(Error 403: Forbidden)
Traceback (most recent call last):
  File "c:\Users\no\AppData\Local\Programs\Python\Python310\lib\site-packages\wandb\sdk\lib\retry.py", line 131, in __call__
    result = self._call_fn(*args, **kwargs)
  File "c:\Users\no\AppData\Local\Programs\Python\Python310\lib\site-packages\wandb\sdk\internal\internal_api.py", line 340, in execute
    return self.client.execute(*args, **kwargs)  # type: ignore
  File "c:\Users\no\AppData\Local\Programs\Python\Python310\lib\site-packages\wandb\vendor\gql-0.2.0\wandb_gql\client.py", line 52, in execute
    result = self._get_result(document, *args, **kwargs)
  File "c:\Users\no\AppData\Local\Programs\Python\Python310\lib\site-packages\wandb\vendor\gql-0.2.0\wandb_gql\client.py", line 60, in _get_result
    return self.transport.execute(document, *args, **kwargs)
  File "c:\Users\no\AppData\Local\Programs\Python\Python310\lib\site-packages\wandb\sdk\lib\gql_request.py", line 59, in execute
    request.raise_for_status()
  File "c:\Users\no\AppData\Local\Programs\Python\Python310\lib\site-packages\requests\models.py", line 1024, in raise_for_status
    raise HTTPError(http_error_msg, response=self)
requests.exceptions.HTTPError: 403 Client Error: Forbidden for url: https://api.wandb.ai/graphql

During handling of the above exception, another exception occurred:

Traceback (most recent call last):
  File "c:\Users\no\AppData\Local\Programs\Python\Python310\lib\site-packages\wandb\sdk\internal\sender.py", line 1007, in send_run
    server_run = self._init_run(run, config_value_dict)
  File "c:\Users\no\AppData\Local\Programs\Python\Python310\lib\site-packages\wandb\sdk\internal\sender.py", line 1079, in _init_run
    server_run, inserted, server_messages = self._api.upsert_run(
  File "c:\Users\no\AppData\Local\Programs\Python\Python310\lib\site-packages\wandb\apis\normalize.py", line 73, in wrapper
    raise err
  File "c:\Users\no\AppData\Local\Programs\Python\Python310\lib\site-packages\wandb\apis\normalize.py", line 41, in wrapper
    return func(*args, **kwargs)
  File "c:\Users\no\AppData\Local\Programs\Python\Python310\lib\site-packages\wandb\sdk\internal\internal_api.py", line 2190, in upsert_run
    response = self.gql(
  File "c:\Users\no\AppData\Local\Programs\Python\Python310\lib\site-packages\wandb\sdk\internal\internal_api.py", line 312, in gql
    ret = self._retry_gql(
  File "c:\Users\no\AppData\Local\Programs\Python\Python310\lib\site-packages\wandb\sdk\lib\retry.py", line 147, in __call__
    retry_timedelta_triggered = check_retry_fn(e)
  File "c:\Users\no\AppData\Local\Programs\Python\Python310\lib\site-packages\wandb\util.py", line 968, in check_retry_fn
    return fallback_retry_fn(e)
  File "c:\Users\no\AppData\Local\Programs\Python\Python310\lib\site-packages\wandb\util.py", line 910, in no_retry_auth
    raise CommError(
wandb.errors.CommError: It appears that you do not have permission to access the requested resource. Please reach out to the project owner to grant you access. If you have the correct permissions, verify that there are no issues with your networking setup.(Error 403: Forbidden)
2024-06-23 15:15:52,873 DEBUG   HandlerThread:24088 [handler.py:handle_request():158] handle_request: status_report
2024-06-23 15:15:52,873 DEBUG   HandlerThread:24088 [handler.py:handle_request():158] handle_request: status_report
2024-06-23 15:15:53,091 DEBUG   HandlerThread:24088 [handler.py:handle_request():158] handle_request: status_report
2024-06-23 15:15:53,422 DEBUG   HandlerThread:24088 [handler.py:handle_request():158] handle_request: status_report
2024-06-23 15:15:54,673 DEBUG   HandlerThread:24088 [handler.py:handle_request():158] handle_request: keepalive
2024-06-23 15:15:55,087 DEBUG   HandlerThread:24088 [handler.py:handle_request():158] handle_request: status_report
2024-06-23 15:15:57,889 DEBUG   HandlerThread:24088 [handler.py:handle_request():158] handle_request: status_report
2024-06-23 15:15:57,907 DEBUG   HandlerThread:24088 [handler.py:handle_request():158] handle_request: status_report
2024-06-23 15:15:58,123 DEBUG   HandlerThread:24088 [handler.py:handle_request():158] handle_request: status_report
2024-06-23 15:15:58,438 DEBUG   HandlerThread:24088 [handler.py:handle_request():158] handle_request: status_report
2024-06-23 15:15:59,705 DEBUG   HandlerThread:24088 [handler.py:handle_request():158] handle_request: keepalive
2024-06-23 15:16:00,105 DEBUG   HandlerThread:24088 [handler.py:handle_request():158] handle_request: status_report
2024-06-23 15:16:02,925 DEBUG   HandlerThread:24088 [handler.py:handle_request():158] handle_request: status_report
2024-06-23 15:16:02,954 DEBUG   HandlerThread:24088 [handler.py:handle_request():158] handle_request: status_report
2024-06-23 15:16:03,154 DEBUG   HandlerThread:24088 [handler.py:handle_request():158] handle_request: status_report
2024-06-23 15:16:03,456 DEBUG   HandlerThread:24088 [handler.py:handle_request():158] handle_request: status_report
2024-06-23 15:16:04,739 DEBUG   HandlerThread:24088 [handler.py:handle_request():158] handle_request: keepalive
2024-06-23 15:16:05,138 DEBUG   HandlerThread:24088 [handler.py:handle_request():158] handle_request: status_report
2024-06-23 15:16:07,955 DEBUG   HandlerThread:24088 [handler.py:handle_request():158] handle_request: status_report
2024-06-23 15:16:07,975 DEBUG   HandlerThread:24088 [handler.py:handle_request():158] handle_request: status_report
2024-06-23 15:16:08,188 DEBUG   HandlerThread:24088 [handler.py:handle_request():158] handle_request: status_report
2024-06-23 15:16:08,488 DEBUG   HandlerThread:24088 [handler.py:handle_request():158] handle_request: status_report
2024-06-23 15:16:09,771 DEBUG   HandlerThread:24088 [handler.py:handle_request():158] handle_request: keepalive
2024-06-23 15:16:10,171 DEBUG   HandlerThread:24088 [handler.py:handle_request():158] handle_request: status_report
